Workbook
Name Slicer_Kategori_Produk: #N/A
Name Slicer_Kota: #N/A
Name Slicer_Metode_Pembayaran: #N/A
Name Slicer_Years__Tanggal: #N/A

Sheet Dashboard
A1: =GETPIVOTDATA("Total_Penjualan",PivotTable!$K$3) -> 35936500 | B1: =GETPIVOTDATA("ID_Transaksi",PivotTable!$E$37) -> 206
A2: =GETPIVOTDATA("Profit",PivotTable!$A$36) -> 26745100 | B2: =GETPIVOTDATA("Margin",PivotTable!$E$31) -> 29745.631
J27: PEFORMA SETIAP KOTA
J28: Medan | K28: Total Penjualan | L28: Profit | M28: Margin
J29: =PivotTable!A3 -> Bandung | K29: =GETPIVOTDATA("Sum of Total_Penjualan",PivotTable!$A$2,"Kota",Table58[[#This Row],[Medan]]) -> 4569000 | L29: =GETPIVOTDATA("Sum of Profit",PivotTable!$A$2,"Kota",Table58[[#This Row],[Medan]]) -> 3431700 | M29: =GETPIVOTDATA("Sum of Margin",PivotTable!$A$2,"Kota",Table58[[#This Row],[Medan]]) -> 758200
J30: =PivotTable!A4 -> Denpasar | K30: =GETPIVOTDATA("Sum of Total_Penjualan",PivotTable!$A$2,"Kota",Table58[[#This Row],[Medan]]) -> 2517000 | L30: =GETPIVOTDATA("Sum of Profit",PivotTable!$A$2,"Kota",Table58[[#This Row],[Medan]]) -> 2020800 | M30: =GETPIVOTDATA("Sum of Margin",PivotTable!$A$2,"Kota",Table58[[#This Row],[Medan]]) -> 330800
J31: =PivotTable!A5 -> Depok | K31: =GETPIVOTDATA("Sum of Total_Penjualan",PivotTable!$A$2,"Kota",Table58[[#This Row],[Medan]]) -> 1566000 | L31: =GETPIVOTDATA("Sum of Profit",PivotTable!$A$2,"Kota",Table58[[#This Row],[Medan]]) -> 1293000 | M31: =GETPIVOTDATA("Sum of Margin",PivotTable!$A$2,"Kota",Table58[[#This Row],[Medan]]) -> 182000
J32: =PivotTable!A6 -> Jakarta | K32: =GETPIVOTDATA("Sum of Total_Penjualan",PivotTable!$A$2,"Kota",Table58[[#This Row],[Medan]]) -> 2009000 | L32: =GETPIVOTDATA("Sum of Profit",PivotTable!$A$2,"Kota",Table58[[#This Row],[Medan]]) -> 1469000 | M32: =GETPIVOTDATA("Sum of Margin",PivotTable!$A$2,"Kota",Table58[[#This Row],[Medan]]) -> 360000
J33: =PivotTable!A7 -> Jakarta Barat | K33: =GETPIVOTDATA("Sum of Total_Penjualan",PivotTable!$A$2,"Kota",Table58[[#This Row],[Medan]]) -> 22000 | L33: =GETPIVOTDATA("Sum of Profit",PivotTable!$A$2,"Kota",Table58[[#This Row],[Medan]]) -> 8800 | M33: =GETPIVOTDATA("Sum of Margin",PivotTable!$A$2,"Kota",Table58[[#This Row],[Medan]]) -> 8800
J34: =PivotTable!A8 -> Jakarta Pusat | K34: =GETPIVOTDATA("Sum of Total_Penjualan",PivotTable!$A$2,"Kota",Table58[[#This Row],[Medan]]) -> 36000 | L34: =GETPIVOTDATA("Sum of Profit",PivotTable!$A$2,"Kota",Table58[[#This Row],[Medan]]) -> 25200 | M34: =GETPIVOTDATA("Sum of Margin",PivotTable!$A$2,"Kota",Table58[[#This Row],[Medan]]) -> 7200
J35: =PivotTable!A9 -> Jakarta Selatan | K35: =GETPIVOTDATA("Sum of Total_Penjualan",PivotTable!$A$2,"Kota",Table58[[#This Row],[Medan]]) -> 3063000 | L35: =GETPIVOTDATA("Sum of Profit",PivotTable!$A$2,"Kota",Table58[[#This Row],[Medan]]) -> 1865400 | M35: =GETPIVOTDATA("Sum of Margin",PivotTable!$A$2,"Kota",Table58[[#This Row],[Medan]]) -> 798400
J36: =PivotTable!A10 -> Malang | K36: =GETPIVOTDATA("Sum of Total_Penjualan",PivotTable!$A$2,"Kota",Table58[[#This Row],[Medan]]) -> 3061000 | L36: =GETPIVOTDATA("Sum of Profit",PivotTable!$A$2,"Kota",Table58[[#This Row],[Medan]]) -> 2536000 | M36: =GETPIVOTDATA("Sum of Margin",PivotTable!$A$2,"Kota",Table58[[#This Row],[Medan]]) -> 350000
B38: Forecast menggunakan model time series Prophet berdasarkan data historis penjualan bulanan (2023–2025).

Sheet Predeksi
A1: Tanggal | B1: Prediksi_Penjualan | C1: Batas_Bawah | D1: Batas_Atas
A2: 44957 | B2: 1560000 | C2: 1050000 | D2: 2050000
A3: 44985 | B3: 10400 | C3: 580000 | D3: 1500000
A4: 45016 | B4: 3200 | C4: -190000 | D4: 840000
A5: 45046 | B5: 19200 | C5: 1370000 | D5: 2390000
A6: 45077 | B6: 11600 | C6: 700000 | D6: 1610000
A7: 45107 | B7: 10600 | C7: 560000 | D7: 1540000
A8: 45138 | B8: 23300 | C8: 1840000 | D8: 2820000
A9: 45169 | B9: 10800 | C9: 610000 | D9: 1580000
A10: 45199 | B10: 14100 | C10: 930000 | D10: 1900000
A11: 45230 | B11: 4300 | C11: -80000 | D11: 930000
A12: 45260 | B12: 16800 | C12: 1200000 | D12: 2180000
A13: 45291 | B13: 18300 | C13: 1370000 | D13: 2340000
... A49: 46387 | B49: 20500 | C49: 1550000 | D49: 2500000

Sheet PivotTable
A2: Row Labels | B2: Sum of Total_Penjualan | C2: Sum of Margin | D2: Sum of Profit
A3: Bandung | B3: 4569000 | C3: 758200 | D3: 3431700 | K3: Row Labels | L3: Sum of Total_Penjualan
A4: Denpasar | B4: 2517000 | C4: 330800 | D4: 2020800 | K4: 2023 | L4: 15792000
A5: Depok | B5: 1566000 | C5: 182000 | D5: 1293000 | K5: 2025 | L5: 20144500
A6: Jakarta | B6: 2009000 | C6: 360000 | D6: 1469000 | K6: Grand Total | L6: 35936500
A7: Jakarta Barat | B7: 22000 | C7: 8800 | D7: 8800
A8: Jakarta Pusat | B8: 36000 | C8: 7200 | D8: 25200
A9: Jakarta Selatan | B9: 3063000 | C9: 798400 | D9: 1865400
A10: Malang | B10: 3061000 | C10: 350000 | D10: 2536000
A11: Medan | B11: 5728000 | C11: 1125600 | D11: 4039600
A12: Semarang | B12: 4270000 | C12: 614800 | D12: 3347800
A13: Surabaya | B13: 5172500 | C13: 793800 | D13: 3981800
A14: Yogyakarta | B14: 3923000 | C14: 798000 | D14: 2726000
A15: Grand Total | B15: 35936500 | C15: 6127600 | D15: 26745100
E16: Row Labels | F16: Sum of Total_Penjualan
E17: Bandung | F17: 4569000
E18: Denpasar | F18: 2517000
A19: PIVOT Total Penjualan Dan Profit | E19: Depok | F19: 1566000
A20: Row Labels | B20: Total Penjualan | C20: Total Profit | E20: Jakarta | F20: 2009000
A21: Jan | B21: 2770500 | C21: 2031000 | E21: Jakarta Barat | F21: 22000
A22: Feb | B22: 2254000 | C22: 1969600 | E22: Jakarta Pusat | F22: 36000
A23: Mar | B23: 1015000 | C23: 631000 | E23: Jakarta Selatan | F23: 3063000
A24: Apr | B24: 3618000 | C24: 2848800 | E24: Malang | F24: 3061000
A25: May | B25: 2705000 | C25: 1989200 | E25: Medan | F25: 5728000
A26: Jun | B26: 2607000 | C26: 1863000 | E26: Semarang | F26: 4270000
A27: Jul | B27: 3867500 | C27: 2468000 | E27: Surabaya | F27: 5172500
A28: Aug | B28: 3200000 | C28: 2475800 | E28: Yogyakarta | F28: 3923000
A29: Sep | B29: 3379000 | C29: 2493400 | E29: Grand Total | F29: 35936500
A30: Oct | B30: 1631000 | C30: 1332800
A31: Nov | B31: 4757500 | C31: 3326200 | E31: Average of Margin
A32: Dec | B32: 4132000 | C32: 3316300 | E32: 29745.631
A33: Grand Total | B33: 35936500 | C33: 26745100
A35: Pivot Provit
A36: Sum of Profit
A37: 26745100 | E37: Row Labels | F37: Count of ID_Transaksi
E38: 2023 | F38: 101
A39: Total Penjualan Produk | E39: 2025 | F39: 105
A40: Sum of Qty | E40: Grand Total | F40: 206
A41: 1152
A42: Total Penjualan Per Kategori
...

Sheet Data Clean
A1: Tanggal | B1: Tahun | C1: ID_Transaksi | D1: Nama_Toko | E1: Kategori_Produk | F1: Nama Produk | G1: Qty | H1: Harga_Satuan | I1: Modal | J1: Margin | K1: Total_Penjualan | L1: Profit | M1: Kota | N1: Metode_Pembayaran | P1: Total Penjualan Per Kota | S1: Total Penjualan per Kategori | V1: Total Penjualan per Toko
A2: 45660 | B2: =YEAR(DataClean[[#This Row],[Tanggal]]) -> 2025 | C2: INV-1001 | D2: Toko Berkah | E2: Makanan | F2: Mie Instan Rasa Ayam | G2: 3 | H2: 3500 | I2: =DataClean[Harga_Satuan]*0.6 -> 2100 | J2: =DataClean[Harga_Satuan]-DataClean[Modal] -> 1400 | K2: =DataClean[[#This Row],[Qty]]*DataClean[[#This Row],[Harga_Satuan]] -> 10500 | L2: =DataClean[Total_Penjualan]-DataClean[Modal] -> 8400 | M2: Jakarta | N2: Tunai | P2: Kota | Q2: Total Penjualan | R2: Profit | S2: Elektronik | T2: =SUMIF(DataClean[Kategori_Produk],S2,DataClean[Total_Penjualan]) -> 9120000 | V2: Grosir Abadi | W2: =SUMIF(DataClean[Nama_Toko],V2,DataClean[Total_Penjualan]) -> 140000
A3: 45679 | B3: =YEAR(DataClean[[#This Row],[Tanggal]]) -> 2025 | C3: TRX-1002 | D3: Supermarket Indah | E3: Minuman | F3: Air Mineral Botol 600Ml | G3: 10 | H3: 4000 | I3: =DataClean[Harga_Satuan]*0.6 -> 2400 | J3: =DataClean[Harga_Satuan]-DataClean[Modal] -> 1600 | K3: =DataClean[[#This Row],[Qty]]*DataClean[[#This Row],[Harga_Satuan]] -> 40000 | L3: =DataClean[Total_Penjualan]-DataClean[Modal] -> 37600 | M3: Bandung | N3: Kartu Debit | P3: Bandung | Q3: =SUMIF(DataClean[Kota],P3,DataClean[Total_Penjualan]) -> 7278500 | R3: =SUMIF(DataClean[Kota],P3,DataClean[Profit]) -> 5279900 | S3: Kecantikan | T3: =SUMIF(DataClean[Kategori_Produk],S3,DataClean[Total_Penjualan]) -> 6165000 | V3: Grosir Andal | W3: =SUMIF(DataClean[Nama_Toko],V3,DataClean[Total_Penjualan]) -> 85000
A4: 45513 | B4: =YEAR(DataClean[[#This Row],[Tanggal]]) -> 2024 | C4: INV-1003 | D4: Grosir Maju Jaya | E4: Elektronik | F4: Lampu Led 10 Watt | G4: 1 | H4: 25000 | I4: =DataClean[Harga_Satuan]*0.6 -> 15000 | J4: =DataClean[Harga_Satuan]-DataClean[Modal] -> 10000 | K4: =DataClean[[#This Row],[Qty]]*DataClean[[#This Row],[Harga_Satuan]] -> 25000 | L4: =DataClean[Total_Penjualan]-DataClean[Modal] -> 10000 | M4: Surabaya | N4: Kartu Kredit | P4: Denpasar | Q4: =SUMIF(DataClean[Kota],P4,DataClean[Total_Penjualan]) -> 3967000 | R4: =SUMIF(DataClean[Kota],P4,DataClean[Profit]) -> 2935600 | S4: Mainan | T4: =SUMIF(DataClean[Kategori_Produk],S4,DataClean[Total_Penjualan]) -> 9695000 | V4: Grosir Baru | W4: =SUMIF(DataClean[Nama_Toko],V4,DataClean[Total_Penjualan]) -> 72000
A5: 45190 | B5: =YEAR(DataClean[[#This Row],[Tanggal]]) -> 2023 | C5: TRX-1004 | D5: Warung Jujur | E5: Kecantikan | F5: Sabun Mandi Cair 500Ml | G5: 2 | H5: 18000 | I5: =DataClean[Harga_Satuan]*0.6 -> 10800 | J5: =DataClean[Harga_Satuan]-DataClean[Modal] -> 7200 | K5: =DataClean[[#This Row],[Qty]]*DataClean[[#This Row],[Harga_Satuan]] -> 36000 | L5: =DataClean[Total_Penjualan]-DataClean[Modal] -> 25200 | M5: Jakarta Pusat | N5: Tunai | P5: Depok | Q5: =SUMIF(DataClean[Kota],P5,DataClean[Total_Penjualan]) -> 3207500 | R5: =SUMIF(DataClean[Kota],P5,DataClean[Profit]) -> 2407400 | S5: Makanan | T5: =SUMIF(DataClean[Kategori_Produk],S5,DataClean[Total_Penjualan]) -> 11166500 | V5: Grosir Bersama | W5: =SUMIF(DataClean[Nama_Toko],V5,DataClean[Total_Penjualan]) -> 20000
A6: 45207 | B6: =YEAR(DataClean[[#This Row],[Tanggal]]) -> 2023 | C6: INV-1005 | D6: Toko Abadi | E6: Makanan | F6: Kopi Robusta 250G | G6: 5 | H6: 30000 | I6: =DataClean[Harga_Satuan]*0.6 -> 18000 | J6: =DataClean[Harga_Satuan]-DataClean[Modal] -> 12000 | K6: =DataClean[[#This Row],[Qty]]*DataClean[[#This Row],[Harga_Satuan]] -> 150000 | L6: =DataClean[Total_Penjualan]-DataClean[Modal] -> 132000 | M6: Depok | N6: Kartu Debit | P6: Jakarta | Q6: =SUMIF(DataClean[Kota],P6,DataClean[Total_Penjualan]) -> 2749000 | R6: =SUMIF(DataClean[Kota],P6,DataClean[Profit]) -> 2016400 | S6: Minuman | T6: =SUMIF(DataClean[Kategori_Produk],S6,DataClean[Total_Penjualan]) -> 4372000 | V6: Grosir Cepat | W6: =SUMIF(DataClean[Nama_Toko],V6,DataClean[Total_Penjualan]) -> 65000
A7: 46004 | B7: =YEAR(DataClean[[#This Row],[Tanggal]]) -> 2025 | C7: TRX-1006 | D7: Pasar Jaya | E7: Pakaian | F7: Kaos Oblong Pria | G7: 4 | H7: 50000 | I7: =DataClean[Harga_Satuan]*0.6 -> 30000 | J7: =DataClean[Harga_Satuan]-DataClean[Modal] -> 20000 | K7: =DataClean[[#This Row],[Qty]]*DataClean[[#This Row],[Harga_Satuan]] -> 200000 | L7: =DataClean[Total_Penjualan]-DataClean[Modal] -> 170000 | M7: Medan | N7: Tunai | P7: Jakarta Barat | Q7: =SUMIF(DataClean[Kota],P7,DataClean[Total_Penjualan]) -> 22000 | R7: =SUMIF(DataClean[Kota],P7,DataClean[Profit]) -> 8800 | S7: Pakaian | T7: =SUMIF(DataClean[Kategori_Produk],S7,DataClean[Total_Penjualan]) -> 14170000 | V7: Grosir Dunia | W7: =SUMIF(DataClean[Nama_Toko],V7,DataClean[Total_Penjualan]) -> 88000
A8: 45175 | B8: =YEAR(DataClean[[#This Row],[Tanggal]]) -> 2023 | C8: INV-1007 | D8: Minimarket Sejahtera | E8: Mainan | F8: Mobil Mainan Plastik | G8: 1 | H8: 15000 | I8: =DataClean[Harga_Satuan]*0.6 -> 9000 | J8: =DataClean[Harga_Satuan]-DataClean[Modal] -> 6000 | K8: =DataClean[[#This Row],[Qty]]*DataClean[[#This Row],[Harga_Satuan]] -> 15000 | L8: =DataClean[Total_Penjualan]-DataClean[Modal] -> 6000 | M8: Bandung | N8: Kartu Kredit | P8: Jakarta Pusat | Q8: =SUMIF(DataClean[Kota],P8,DataClean[Total_Penjualan]) -> 36000 | R8: =SUMIF(DataClean[Kota],P8,DataClean[Profit]) -> 25200 | V8: Grosir Emas | W8: =SUMIF(DataClean[Nama_Toko],V8,DataClean[Total_Penjualan]) -> 180000
A9: 45598 | B9: =YEAR(DataClean[[#This Row],[Tanggal]]) -> 2024 | C9: TRX-1008 | D9: Toko Sari | E9: Makanan | F9: Snack Keripik Kentang | G9: 8 | H9: 12500 | I9: =DataClean[Harga_Satuan]*0.6 -> 7500 | J9: =DataClean[Harga_Satuan]-DataClean[Modal] -> 5000 | K9: =DataClean[[#This Row],[Qty]]*DataClean[[#This Row],[Harga_Satuan]] -> 100000 | L9: =DataClean[Total_Penjualan]-DataClean[Modal] -> 92500 | M9: Semarang | N9: Tunai | P9: Jakarta Selatan | Q9: =SUMIF(DataClean[Kota],P9,DataClean[Total_Penjualan]) -> 3499000 | R9: =SUMIF(DataClean[Kota],P9,DataClean[Profit]) -> 2243800 | S9: Total Penjualan | T9: =SUM(DataClean[Total_Penjualan]) -> 54688500 | V9: Grosir Hebat | W9: =SUMIF(DataClean[Nama_Toko],V9,DataClean[Total_Penjualan]) -> 150000
A10: 44956 | B10: =YEAR(DataClean[[#This Row],[Tanggal]]) -> 2023 | C10: INV-1009 | D10: Toko Sari | E10: Minuman | F10: Teh Celup Kotak Kecil | G10: 2 | H10: 7000 | I10: =DataClean[Harga_Satuan]*0.6 -> 4200 | J10: =DataClean[Harga_Satuan]-DataClean[Modal] -> 2800 | K10: =DataClean[[#This Row],[Qty]]*DataClean[[#This Row],[Harga_Satuan]] -> 14000 | L10: =DataClean[Total_Penjualan]-DataClean[Modal] -> 9800 | M10: Surabaya | N10: Kartu Debit | P10: Malang | Q10: =SUMIF(DataClean[Kota],P10,DataClean[Total_Penjualan]) -> 6239000 | R10: =SUMIF(DataClean[Kota],P10,DataClean[Profit]) -> 4715000 | S10: Jumlah Transaksi | T10: 300 | V10: Grosir Hemat | W10: =SUMIF(DataClean[Nama_Toko],V10,DataClean[Total_Penjualan]) -> 160000
A11: 45241 | B11: =YEAR(DataClean[[#This Row],[Tanggal]]) -> 2023 | C11: INV-1010 | D11: Toko Sembako | E11: Elektronik | F11: Baterai Aa Pack 4 | G11: 3 | H11: 30000 | I11: =DataClean[Harga_Satuan]*0.6 -> 18000 | J11: =DataClean[Harga_Satuan]-DataClean[Modal] -> 12000 | K11: =DataClean[[#This Row],[Qty]]*DataClean[[#This Row],[Harga_Satuan]] -> 90000 | L11: =DataClean[Total_Penjualan]-DataClean[Modal] -> 72000 | M11: Denpasar | N11: Kartu Kredit | P11: Medan | Q11: =SUMIF(DataClean[Kota],P11,DataClean[Total_Penjualan]) -> 7456000 | R11: =SUMIF(DataClean[Kota],P11,DataClean[Profit]) -> 5466400 | S11: Rata-Rata Trasanksi | T11: =AVERAGE(DataClean[Total_Penjualan]) -> 182295 | V11: Grosir Hemat Banget | W11: =SUMIF(DataClean[Nama_Toko],V11,DataClean[Total_Penjualan]) -> 120000
A12: 45830 | B12: =YEAR(DataClean[[#This Row],[Tanggal]]) -> 2025 | C12: TRX-1011 | D12: Warung Depan | E12: Kecantikan | F12: Shampoo Anti Ketombe | G12: 1 | H12: 22000 | I12: =DataClean[Harga_Satuan]*0.6 -> 13200 | J12: =DataClean[Harga_Satuan]-DataClean[Modal] -> 8800 | K12: =DataClean[[#This Row],[Qty]]*DataClean[[#This Row],[Harga_Satuan]] -> 22000 | L12: =DataClean[Total_Penjualan]-DataClean[Modal] -> 8800 | M12: Jakarta Barat | N12: Tunai | P12: Semarang | Q12: =SUMIF(DataClean[Kota],P12,DataClean[Total_Penjualan]) -> 6111000 | R12: =SUMIF(DataClean[Kota],P12,DataClean[Profit]) -> 4372500 | S12: Penjualan Terbesar | T12: =MAX(DataClean[Total_Penjualan]) -> 800000 | V12: Grosir Kiloan | W12: =SUMIF(DataClean[Nama_Toko],V12,DataClean[Total_Penjualan]) -> 120000
A13: 45420 | B13: =YEAR(DataClean[[#This Row],[Tanggal]]) -> 2024 | C13: INV-1012 | D13: Toko Hoki | E13: Makanan | F13: Biskuit Rasa Coklat | G13: 6 | H13: 8000 | I13: =DataClean[Harga_Satuan]*0.6 -> 4800 | J13: =DataClean[Harga_Satuan]-DataClean[Modal] -> 3200 | K13: =DataClean[[#This Row],[Qty]]*DataClean[[#This Row],[Harga_Satuan]] -> 48000 | L13: =DataClean[Total_Penjualan]-DataClean[Modal] -> 43200 | M13: Malang | N13: Kartu Debit | P13: Surabaya | Q13: =SUMIF(DataClean[Kota],P13,DataClean[Total_Penjualan]) -> 7371500 | R13: =SUMIF(DataClean[Kota],P13,DataClean[Profit]) -> 5583200 | S13: Total Produk Terjual | T13: =SUM(DataClean[Qty]) -> 1596 | V13: Grosir Lama | W13: =SUMIF(DataClean[Nama_Toko],V13,DataClean[Total_Penjualan]) -> 72000
A14: 45318 | B14: =YEAR(DataClean[[#This Row],[Tanggal]]) -> 2024 | C14: TRX-1013 | D14: Pasar Rame | E14: Pakaian | F14: Celana Jeans Biru | G14: 1 | H14: 350000 | I14: =DataClean[Harga_Satuan]*0.6 -> 210000 | J14: =DataClean[Harga_Satuan]-DataClean[Modal] -> 140000 | K14: =DataClean[[#This Row],[Qty]]*DataClean[[#This Row],[Harga_Satuan]] -> 350000 | L14: =DataClean[Total_Penjualan]-DataClean[Modal] -> 140000 | M14: Yogyakarta | N14: Kartu Kredit | P14: Yogyakarta | Q14: =SUMIF(DataClean[Kota],P14,DataClean[Total_Penjualan]) -> 6752000 | R14: =SUMIF(DataClean[Kota],P14,DataClean[Profit]) -> 4800200 | S14: Profit | T14: =SUM((DataClean[Harga_Satuan]-DataClean[Modal])*DataClean[Qty]) -> 140000 | V14: Grosir Laris | W14: =SUMIF(DataClean[Nama_Toko],V14,DataClean[Total_Penjualan]) -> 203000
A15: 45111 | B15: =YEAR(DataClean[[#This Row],[Tanggal]]) -> 2023 | C15: INV-1014 | D15: Grosir Laris | E15: Mainan | F15: Boneka Barbie Original | G15: 1 | H15: 75000 | I15: =DataClean[Harga_Satuan]*0.6 -> 45000 | J15: =DataClean[Harga_Satuan]-DataClean[Modal] -> 30000 | K15: =DataClean[[#This Row],[Qty]]*DataClean[[#This Row],[Harga_Satuan]] -> 75000 | L15: =DataClean[Total_Penjualan]-DataClean[Modal] -> 30000 | M15: Medan | N15: Tunai | S15: Total_Invoice | T15: =SUMIFS(DataClean[Total_Penjualan], DataClean[ID_Transaksi], DataClean[ID_Transaksi]) -> 75000 | V15: Grosir Maju | W15: =SUMIF(DataClean[Nama_Toko],V15,DataClean[Total_Penjualan]) -> 165000
A16: 45322 | B16: =YEAR(DataClean[[#This Row],[Tanggal]]) -> 2024 | C16: TRX-1015 | D16: Minimarket Cepat | E16: Makanan | F16: Sereal Sarapan Kotak | G16: 4 | H16: 28000 | I16: =DataClean[Harga_Satuan]*0.6 -> 16800 | J16: =DataClean[Harga_Satuan]-DataClean[Modal] -> 11200 | K16: =DataClean[[#This Row],[Qty]]*DataClean[[#This Row],[Harga_Satuan]] -> 112000 | L16: =DataClean[Total_Penjualan]-DataClean[Modal] -> 95200 | M16: Bandung | N16: Tunai | V16: Grosir Makmur | W16: =SUMIF(DataClean[Nama_Toko],V16,DataClean[Total_Penjualan]) -> 90000
A17: 45749 | B17: =YEAR(DataClean[[#This Row],[Tanggal]]) -> 2025 | C17: INV-1016 | D17: Toko Murni | E17: Minuman | F17: Jus Buah Segar 1L | G17: 2 | H17: 20000 | I17: =DataClean[Harga_Satuan]*0.6 -> 12000 | J17: =DataClean[Harga_Satuan]-DataClean[Modal] -> 8000 | K17: =DataClean[[#This Row],[Qty]]*DataClean[[#This Row],[Harga_Satuan]] -> 40000 | L17: =DataClean[Total_Penjualan]-DataClean[Modal] -> 28000 | M17: Semarang | N17: Kartu Debit | P17: =COUNTA(DataClean[ID_Transaksi]) -> 300 | S17: Total Penjualan Dengan Metode Pembayaran | V17: Grosir Mantap | W17: =SUMIF(DataClean[Nama_Toko],V17,DataClean[Total_Penjualan]) -> 132000
A18: 45038 | B18: =YEAR(DataClean[[#This Row],[Tanggal]]) -> 2023 | C18: TRX-1017 | D18: Warung Santai | E18: Elektronik | F18: Kabel Data Usb C | G18: 5 | H18: 15000 | I18: =DataClean[Harga_Satuan]*0.6 -> 9000 | J18: =DataClean[Harga_Satuan]-DataClean[Modal] -> 6000 | K18: =DataClean[[#This Row],[Qty]]*DataClean[[#This Row],[Harga_Satuan]] -> 75000 | L18: =DataClean[Total_Penjualan]-DataClean[Modal] -> 66000 | M18: Surabaya | N18: Kartu Kredit | S18: Tunai | T18: =SUMIF(DataClean[Metode_Pembayaran], S18, DataClean[Total_Penjualan]) -> 24772000 | V18: Grosir Mega | W18: =SUMIF(DataClean[Nama_Toko],V18,DataClean[Total_Penjualan]) -> 90000
A19: 45596 | B19: =YEAR(DataClean[[#This Row],[Tanggal]]) -> 2024 | C19: INV-1018 | D19: Gudang Besar | E19: Kecantikan | F19: Lipstik Warna Merah | G19: 1 | H19: 55000 | I19: =DataClean[Harga_Satuan]*0.6 -> 33000 | J19: =DataClean[Harga_Satuan]-DataClean[Modal] -> 22000 | K19: =DataClean[[#This Row],[Qty]]*DataClean[[#This Row],[Harga_Satuan]] -> 55000 | L19: =DataClean[Total_Penjualan]-DataClean[Modal] -> 22000 | M19: Denpasar | N19: Tunai | P19: =AVERAGE(DataClean[Margin]) -> 32964.667 | S19: Kartu Kredit | T19: =SUMIF(DataClean[Metode_Pembayaran], S19, DataClean[Total_Penjualan]) -> 19090000 | V19: Grosir Mulia | W19: =SUMIF(DataClean[Nama_Toko],V19,DataClean[Total_Penjualan]) -> 105000
A20: 45363 | B20: =YEAR(DataClean[[#This Row],[Tanggal]]) -> 2024 | C20: TRX-1019 | D20: Gudang Besar | E20: Makanan | F20: Tepung Terigu 1 Kg | G20: 10 | H20: 11000 | I20: =DataClean[Harga_Satuan]*0.6 -> 6600 | J20: =DataClean[Harga_Satuan]-DataClean[Modal] -> 4400 | K20: =DataClean[[#This Row],[Qty]]*DataClean[[#This Row],[Harga_Satuan]] -> 110000 | L20: =DataClean[Total_Penjualan]-DataClean[Modal] -> 103400 | M20: Jakarta | N20: Kartu Debit | S20: Kartu Debit | T20: =SUMIF(DataClean[Metode_Pembayaran], S20, DataClean[Total_Penjualan]) -> 10826500 | V20: Grosir Murah Banget | W20: =SUMIF(DataClean[Nama_Toko],V20,DataClean[Total_Penjualan]) -> 122500
A21: 45907 | B21: =YEAR(DataClean[[#This Row],[Tanggal]]) -> 2025 | C21: INV-1020 | D21: Pasar Pagi | E21: Pakaian | F21: Kemeja Batik Lengan Panjang | G21: 3 | H21: 120000 | I21: =DataClean[Harga_Satuan]*0.6 -> 72000 | J21: =DataClean[Harga_Satuan]-DataClean[Modal] -> 48000 | K21: =DataClean[[#This Row],[Qty]]*DataClean[[#This Row],[Harga_Satuan]] -> 360000 | L21: =DataClean[Total_Penjualan]-DataClean[Modal] -> 288000 | M21: Medan | N21: Tunai | V21: Grosir Pangan | W21: =SUMIF(DataClean[Nama_Toko],V21,DataClean[Total_Penjualan]) -> 81000
A22: 45379 | B22: =YEAR(DataClean[[#This Row],[Tanggal]]) -> 2024 | C22: TRX-1021 | D22: Minimarket Istimewa | E22: Mainan | F22: Puzzle Kayu Edukasi | G22: 2 | H22: 45000 | I22: =DataClean[Harga_Satuan]*0.6 -> 27000 | J22: =DataClean[Harga_Satuan]-DataClean[Modal] -> 18000 | K22: =DataClean[[#This Row],[Qty]]*DataClean[[#This Row],[Harga_Satuan]] -> 90000 | L22: =DataClean[Total_Penjualan]-DataClean[Modal] -> 63000 | M22: Yogyakarta | N22: Kartu Kredit | V22: Grosir Penuh | W22: =SUMIF(DataClean[Nama_Toko],V22,DataClean[Total_Penjualan]) -> 100000
A23: 45338 | B23: =YEAR(DataClean[[#This Row],[Tanggal]]) -> 2024 | C23: INV-1022 | D23: Toko Serba Ada | E23: Makanan | F23: Telur Ayam Ras Pack 10 | G23: 12 | H23: 20000 | I23: =DataClean[Harga_Satuan]*0.6 -> 12000 | J23: =DataClean[Harga_Satuan]-DataClean[Modal] -> 8000 | K23: =DataClean[[#This Row],[Qty]]*DataClean[[#This Row],[Harga_Satuan]] -> 240000 | L23: =DataClean[Total_Penjualan]-DataClean[Modal] -> 228000 | M23: Malang | N23: Tunai | V23: Grosir Pertiwi | W23: =SUMIF(DataClean[Nama_Toko],V23,DataClean[Total_Penjualan]) -> 249500
A24: 45585 | B24: =YEAR(DataClean[[#This Row],[Tanggal]]) -> 2024 | C24: TRX-1023 | D24: Grosir Murah Banget | E24: Minuman | F24: Susu Uht Full Cream 1L | G24: 7 | H24: 17500 | I24: =DataClean[Harga_Satuan]*0.6 -> 10500 | J24: =DataClean[Harga_Satuan]-DataClean[Modal] -> 7000 | K24: =DataClean[[#This Row],[Qty]]*DataClean[[#This Row],[Harga_Satuan]] -> 122500 | L24: =DataClean[Total_Penjualan]-DataClean[Modal] -> 112000 | M24: Bandung | N24: Kartu Debit | V24: Grosir Pintar | W24: =SUMIF(DataClean[Nama_Toko],V24,DataClean[Total_Penjualan]) -> 110000
A25: 45186 | B25: =YEAR(DataClean[[#This Row],[Tanggal]]) -> 2023 | C25: INV-1024 | D25: Warung Pojok | E25: Elektronik | F25: Power Bank 10000Mah | G25: 1 | H25: 150000 | I25: =DataClean[Harga_Satuan]*0.6 -> 90000 | J25: =DataClean[Harga_Satuan]-DataClean[Modal] -> 60000 | K25: =DataClean[[#This Row],[Qty]]*DataClean[[#This Row],[Harga_Satuan]] -> 150000 | L25: =DataClean[Total_Penjualan]-DataClean[Modal] -> 60000 | M25: Semarang | N25: Kartu Kredit | V25: Grosir Pusat | W25: =SUMIF(DataClean[Nama_Toko],V25,DataClean[Total_Penjualan]) -> 108000
A26: 44985 | B26: =YEAR(DataClean[[#This Row],[Tanggal]]) -> 2023 | C26: TRX-1025 | D26: Gudang Cepat | E26: Kecantikan | F26: Pelembab Wajah Siang | G26: 3 | H26: 40000 | I26: =DataClean[Harga_Satuan]*0.6 -> 24000 | J26: =DataClean[Harga_Satuan]-DataClean[Modal] -> 16000 | K26: =DataClean[[#This Row],[Qty]]*DataClean[[#This Row],[Harga_Satuan]] -> 120000 | L26: =DataClean[Total_Penjualan]-DataClean[Modal] -> 96000 | M26: Surabaya | N26: Tunai | V26: Grosir Pusat Kota | W26: =SUMIF(DataClean[Nama_Toko],V26,DataClean[Total_Penjualan]) -> 90000
A27: 45560 | B27: =YEAR(DataClean[[#This Row],[Tanggal]]) -> 2024 | C27: INV-1026 | D27: Toko Lengkap | E27: Makanan | F27: Gula Pasir 1 Kg | G27: 9 | H27: 13500 | I27: =DataClean[Harga_Satuan]*0.6 -> 8100 | J27: =DataClean[Harga_Satuan]-DataClean[Modal] -> 5400 | K27: =DataClean[[#This Row],[Qty]]*DataClean[[#This Row],[Harga_Satuan]] -> 121500 | L27: =DataClean[Total_Penjualan]-DataClean[Modal] -> 113400 | M27: Depok | N27: Kartu Debit | V27: Grosir Sakti | W27: =SUMIF(DataClean[Nama_Toko],V27,DataClean[Total_Penjualan]) -> 98000
A28: 45725 | B28: =YEAR(DataClean[[#This Row],[Tanggal]]) -> 2025 | C28: TRX-1027 | D28: Pasar Malam | E28: Pakaian | F28: Sepatu Sneaker Kasual | G28: 1 | H28: 450000 | I28: =DataClean[Harga_Satuan]*0.6 -> 270000 | J28: =DataClean[Harga_Satuan]-DataClean[Modal] -> 180000 | K28: =DataClean[[#This Row],[Qty]]*DataClean[[#This Row],[Harga_Satuan]] -> 450000 | L28: =DataClean[Total_Penjualan]-DataClean[Modal] -> 180000 | M28: Jakarta Selatan | N28: Tunai | V28: Grosir Segar | W28: =SUMIF(DataClean[Nama_Toko],V28,DataClean[Total_Penjualan]) -> 392000
A29: 45841 | B29: =YEAR(DataClean[[#This Row],[Tanggal]]) -> 2025 | C29: INV-1028 | D29: Minimarket Tepat | E29: Mainan | F29: Set Mainan Masak-Masakan | G29: 4 | H29: 60000 | I29: =DataClean[Harga_Satuan]*0.6 -> 36000 | J29: =DataClean[Harga_Satuan]-DataClean[Modal] -> 24000 | K29: =DataClean[[#This Row],[Qty]]*DataClean[[#This Row],[Harga_Satuan]] -> 240000 | L29: =DataClean[Total_Penjualan]-DataClean[Modal] -> 204000 | M29: Medan | N29: Kartu Kredit | V29: Grosir Sempurna | W29: =SUMIF(DataClean[Nama_Toko],V29,DataClean[Total_Penjualan]) -> 75000
A30: 45831 | B30: =YEAR(DataClean[[#This Row],[Tanggal]]) -> 2025 | C30: TRX-1029 | D30: Toko Bersama | E30: Makanan | F30: Roti Tawar Gandum | G30: 5 | H30: 18000 | I30: =DataClean[Harga_Satuan]*0.6 -> 10800 | J30: =DataClean[Harga_Satuan]-DataClean[Modal] -> 7200 | K30: =DataClean[[#This Row],[Qty]]*DataClean[[#This Row],[Harga_Satuan]] -> 90000 | L30: =DataClean[Total_Penjualan]-DataClean[Modal] -> 79200 | M30: Yogyakarta | N30: Tunai | V30: Grosir Senja | W30: =SUMIF(DataClean[Nama_Toko],V30,DataClean[Total_Penjualan]) -> 60000
A31: 45020 | B31: =YEAR(DataClean[[#This Row],[Tanggal]]) -> 2023 | C31: INV-1030 | D31: Grosir Hebat | E31: Minuman | F31: Kopi Bubuk Hitam 100G | G31: 15 | H31: 10000 | I31: =DataClean[Harga_Satuan]*0.6 -> 6000 | J31: =DataClean[Harga_Satuan]-DataClean[Modal] -> 4000 | K31: =DataClean[[#This Row],[Qty]]*DataClean[[#This Row],[Harga_Satuan]] -> 150000 | L31: =DataClean[Total_Penjualan]-DataClean[Modal] -> 144000 | M31: Malang | N31: Kartu Debit | V31: Grosir Tani | W31: =SUMIF(DataClean[Nama_Toko],V31,DataClean[Total_Penjualan]) -> 80000
A32: 45841 | B32: =YEAR(DataClean[[#This Row],[Tanggal]]) -> 2025 | C32: TRX-1031 | D32: Warung Kita | E32: Elektronik | F32: Headset Bluetooth | G32: 2 | H32: 85000 | I32: =DataClean[Harga_Satuan]*0.6 -> 51000 | J32: =DataClean[Harga_Satuan]-DataClean[Modal] -> 34000 | K32: =DataClean[[#This Row],[Qty]]*DataClean[[#This Row],[Harga_Satuan]] -> 170000 | L32: =DataClean[Total_Penjualan]-DataClean[Modal] -> 119000 | M32: Bandung | N32: Kartu Kredit | V32: Grosir Terdepan | W32: =SUMIF(DataClean[Nama_Toko],V32,DataClean[Total_Penjualan]) -> 80000
... A241: 45033 | B241: =YEAR(DataClean[[#This Row],[Tanggal]]) -> 2023 | C241: INV-1240 | D241: Grosir Maju | E241: Minuman | F241: Susu Bubuk Full Cream 400G | G241: 3 | H241: 55000 | I241: =DataClean[Harga_Satuan]*0.6 -> 33000 | J241: =DataClean[Harga_Satuan]-DataClean[Modal] -> 22000 | K241: =DataClean[[#This Row],[Qty]]*DataClean[[#This Row],[Harga_Satuan]] -> 165000 | L241: =DataClean[Total_Penjualan]-DataClean[Modal] -> 132000 | M241: Semarang | N241: Kartu Debit | V241: Toko Sari | W241: =SUMIF(DataClean[Nama_Toko],V241,DataClean[Total_Penjualan]) -> 114000
A242: 45787 | B242: =YEAR(DataClean[[#This Row],[Tanggal]]) -> 2025 | C242: TRX-1241 | D242: Warung Baru | E242: Elektronik | F242: Headphone Noise Cancelling | G242: 1 | H242: 450000 | I242: =DataClean[Harga_Satuan]*0.6 -> 270000 | J242: =DataClean[Harga_Satuan]-DataClean[Modal] -> 180000 | K242: =DataClean[[#This Row],[Qty]]*DataClean[[#This Row],[Harga_Satuan]] -> 450000 | L242: =DataClean[Total_Penjualan]-DataClean[Modal] -> 180000 | M242: Surabaya | N242: Kartu Kredit | V242: Total | W242: 109527000
A243: 46015 | B243: =YEAR(DataClean[[#This Row],[Tanggal]]) -> 2025 | C243: INV-1242 | D243: Gudang Barokah | E243: Kecantikan | F243: Serum Anti Aging Malam | G243: 2 | H243: 120000 | I243: =DataClean[Harga_Satuan]*0.6 -> 72000 | J243: =DataClean[Harga_Satuan]-DataClean[Modal] -> 48000 | K243: =DataClean[[#This Row],[Qty]]*DataClean[[#This Row],[Harga_Satuan]] -> 240000 | L243: =DataClean[Total_Penjualan]-DataClean[Modal] -> 168000 | M243: Denpasar | N243: Tunai
A244: 45881 | B244: =YEAR(DataClean[[#This Row],[Tanggal]]) -> 2025 | C244: TRX-1243 | D244: Toko Hoki | E244: Makanan | F244: Pasta Gigi Anak | G244: 5 | H244: 18000 | I244: =DataClean[Harga_Satuan]*0.6 -> 10800 | J244: =DataClean[Harga_Satuan]-DataClean[Modal] -> 7200 | K244: =DataClean[[#This Row],[Qty]]*DataClean[[#This Row],[Harga_Satuan]] -> 90000 | L244: =DataClean[Total_Penjualan]-DataClean[Modal] -> 79200 | M244: Jakarta | N244: Kartu Debit
A245: 45365 | B245: =YEAR(DataClean[[#This Row],[Tanggal]]) -> 2024 | C245: INV-1244 | D245: Pasar Jaya | E245: Pakaian | F245: Daster Batik Casual | G245: 6 | H245: 75000 | I245: =DataClean[Harga_Satuan]*0.6 -> 45000 | J245: =DataClean[Harga_Satuan]-DataClean[Modal] -> 30000 | K245: =DataClean[[#This Row],[Qty]]*DataClean[[#This Row],[Harga_Satuan]] -> 450000 | L245: =DataClean[Total_Penjualan]-DataClean[Modal] -> 405000 | M245: Medan | N245: Tunai
A246: 45775 | B246: =YEAR(DataClean[[#This Row],[Tanggal]]) -> 2025 | C246: TRX-1245 | D246: Minimarket Cepat | E246: Mainan | F246: Mainan Pesawat Mini | G246: 12 | H246: 15000 | I246: =DataClean[Harga_Satuan]*0.6 -> 9000 | J246: =DataClean[Harga_Satuan]-DataClean[Modal] -> 6000 | K246: =DataClean[[#This Row],[Qty]]*DataClean[[#This Row],[Harga_Satuan]] -> 180000 | L246: =DataClean[Total_Penjualan]-DataClean[Modal] -> 171000 | M246: Yogyakarta | N246: Kartu Kredit
A247: 45933 | B247: =YEAR(DataClean[[#This Row],[Tanggal]]) -> 2025 | C247: INV-1246 | D247: Toko Mulia | E247: Makanan | F247: Mentega Putih 500G | G247: 4 | H247: 32000 | I247: =DataClean[Harga_Satuan]*0.6 -> 19200 | J247: =DataClean[Harga_Satuan]-DataClean[Modal] -> 12800 | K247: =DataClean[[#This Row],[Qty]]*DataClean[[#This Row],[Harga_Satuan]] -> 128000 | L247: =DataClean[Total_Penjualan]-DataClean[Modal] -> 108800 | M247: Malang | N247: Tunai
A248: 45063 | B248: =YEAR(DataClean[[#This Row],[Tanggal]]) -> 2023 | C248: TRX-1247 | D248: Grosir Laris | E248: Minuman | F248: Jus Jambu Biji 1L | G248: 8 | H248: 16000 | I248: =DataClean[Harga_Satuan]*0.6 -> 9600 | J248: =DataClean[Harga_Satuan]-DataClean[Modal] -> 6400 | K248: =DataClean[[#This Row],[Qty]]*DataClean[[#This Row],[Harga_Satuan]] -> 128000 | L248: =DataClean[Total_Penjualan]-DataClean[Modal] -> 118400 | M248: Bandung | N248: Kartu Debit
...

Sheet Data Mentah
A1: Tanggal | B1: ID_Transaksi | C1: Nama_Toko | D1: Kategori_Produk | E1: Nama Produk | F1: Qty | G1: Harga_Satuan | H1: Total_Penjualan | I1: Kota | J1: Metode_Pembayaran | M1: Tanggal | N1: ID_Transaksi | O1: Nama_Toko | P1: Kategori_Produk | Q1: Nama Produk | R1: Qty | S1: Harga_Satuan | T1: Total_Penjualan | U1: Kota | V1: Metode_Pembayaran
A2: 01/01/2023 | B2: INV-1001 | C2: Toko Berkah | D2: Makanan | E2: mie Instan Rasa Ayam | F2: 3 | G2: 3500 | H2: 10500 | I2: Jakarta | J2: TUNAI | M2: =DATEVALUE(SUBSTITUTE(SUBSTITUTE(SUBSTITUTE(SUBSTITUTE(SUBSTITUTE(SUBSTITUTE(SUBSTITUTE(SUBSTITUTE(SUBSTITUTE(SUBSTITUTE(SUBSTITUTE(SUBSTITUTE(Table1[[#This Row],[Tanggal]],"Jan", "Jan"),"Feb","Feb"),"Mar","Mar"),"Apr","Apr"),"Mei","May"),"Jun","Jun"),"Jul","Jul"),"Agu","Aug"),"Sep","Sep"),"Okt","Oct"),"Nov","Nov"),"Des","Dec")) -> 44927 | N2: =Table1[[#This Row],[ID_Transaksi]] -> INV-1001 | O2: Toko Berkah | P2: =PROPER(TRIM(Table1[[#This Row],[Kategori_Produk]])) -> Makanan | Q2: =PROPER(TRIM(Table1[Nama Produk])) -> Mie Instan Rasa Ayam | R2: =Table1[[#This Row],[Qty]] -> 3 | S2: =SUBSTITUTE(SUBSTITUTE(Table1[[#This Row],[Harga_Satuan]],"Rp.",""),".","") -> 3500 | T2: =Table1[[#This Row],[Total_Penjualan]] -> 10500 | U2: =PROPER(Table1[[#This Row],[Kota]]) -> Jakarta | V2: =PROPER(Table1[[#This Row],[Metode_Pembayaran]]) -> Tunai
A3: 02/01/2023 | B3: TRX-1002 | C3: SuperMarket Indah | D3: Minuman | E3: Air Mineral Botol 600ml | F3: 10 | G3: 4000 | H3: 40000 | I3: BANDUNG | J3: Kartu debit | M3: =DATEVALUE(SUBSTITUTE(SUBSTITUTE(SUBSTITUTE(SUBSTITUTE(SUBSTITUTE(SUBSTITUTE(SUBSTITUTE(SUBSTITUTE(SUBSTITUTE(SUBSTITUTE(SUBSTITUTE(SUBSTITUTE(Table1[[#This Row],[Tanggal]],"Jan", "Jan"),"Feb","Feb"),"Mar","Mar"),"Apr","Apr"),"Mei","May"),"Jun","Jun"),"Jul","Jul"),"Agu","Aug"),"Sep","Sep"),"Okt","Oct"),"Nov","Nov"),"Des","Dec")) -> 44928 | N3: =Table1[[#This Row],[ID_Transaksi]] -> TRX-1002 | O3: SuperMarket Indah | P3: =PROPER(TRIM(Table1[[#This Row],[Kategori_Produk]])) -> Minuman | Q3: =PROPER(TRIM(Table1[Nama Produk])) -> Air Mineral Botol 600Ml | R3: =Table1[[#This Row],[Qty]] -> 10 | S3: =SUBSTITUTE(SUBSTITUTE(Table1[[#This Row],[Harga_Satuan]],"Rp.",""),".","") -> 4000 | T3: =Table1[[#This Row],[Total_Penjualan]] -> 40000 | U3: =PROPER(Table1[[#This Row],[Kota]]) -> Bandung | V3: =PROPER(Table1[[#This Row],[Metode_Pembayaran]]) -> Kartu Debit
A4: 15/01/2023 | B4: INV-1003 | C4: Grosir Maju Jaya | D4: ELEKTRONIK | E4: Lampu LED 10 Watt | F4: 1 | G4: 25000 | H4: 25000 | I4: Surabaya | J4: KARTU KREDIT | M4: =DATEVALUE(SUBSTITUTE(SUBSTITUTE(SUBSTITUTE(SUBSTITUTE(SUBSTITUTE(SUBSTITUTE(SUBSTITUTE(SUBSTITUTE(SUBSTITUTE(SUBSTITUTE(SUBSTITUTE(SUBSTITUTE(Table1[[#This Row],[Tanggal]],"Jan", "Jan"),"Feb","Feb"),"Mar","Mar"),"Apr","Apr"),"Mei","May"),"Jun","Jun"),"Jul","Jul"),"Agu","Aug"),"Sep","Sep"),"Okt","Oct"),"Nov","Nov"),"Des","Dec")) -> 44941 | N4: =Table1[[#This Row],[ID_Transaksi]] -> INV-1003 | O4: Grosir Maju Jaya | P4: =PROPER(TRIM(Table1[[#This Row],[Kategori_Produk]])) -> Elektronik | Q4: =PROPER(TRIM(Table1[Nama Produk])) -> Lampu Led 10 Watt | R4: =Table1[[#This Row],[Qty]] -> 1 | S4: =SUBSTITUTE(SUBSTITUTE(Table1[[#This Row],[Harga_Satuan]],"Rp.",""),".","") -> 25000 | T4: =Table1[[#This Row],[Total_Penjualan]] -> 25000 | U4: =PROPER(Table1[[#This Row],[Kota]]) -> Surabaya | V4: =PROPER(Table1[[#This Row],[Metode_Pembayaran]]) -> Kartu Kredit
A5: 28/01/2023 | B5: TRX-1004 | C5: Warung Jujur | D5: kecantikan | E5: Sabun Mandi Cair 500ml | F5: 2 | G5: 18000 | H5: 36000 | I5: JAKARTA PUSAT | J5: tunai | M5: =DATEVALUE(SUBSTITUTE(SUBSTITUTE(SUBSTITUTE(SUBSTITUTE(SUBSTITUTE(SUBSTITUTE(SUBSTITUTE(SUBSTITUTE(SUBSTITUTE(SUBSTITUTE(SUBSTITUTE(SUBSTITUTE(Table1[[#This Row],[Tanggal]],"Jan", "Jan"),"Feb","Feb"),"Mar","Mar"),"Apr","Apr"),"Mei","May"),"Jun","Jun"),"Jul","Jul"),"Agu","Aug"),"Sep","Sep"),"Okt","Oct"),"Nov","Nov"),"Des","Dec")) -> 44954 | N5: =Table1[[#This Row],[ID_Transaksi]] -> TRX-1004 | O5: Warung Jujur | P5: =PROPER(TRIM(Table1[[#This Row],[Kategori_Produk]])) -> Kecantikan | Q5: =PROPER(TRIM(Table1[Nama Produk])) -> Sabun Mandi Cair 500Ml | R5: =Table1[[#This Row],[Qty]] -> 2 | S5: =SUBSTITUTE(SUBSTITUTE(Table1[[#This Row],[Harga_Satuan]],"Rp.",""),".","") -> 18000 | T5: =Table1[[#This Row],[Total_Penjualan]] -> 36000 | U5: =PROPER(Table1[[#This Row],[Kota]]) -> Jakarta Pusat | V5: =PROPER(Table1[[#This Row],[Metode_Pembayaran]]) -> Tunai
A6: 01/01/2023 | B6: INV-1005 | C6: Toko Abadi | D6: MAKANAN | E6: KOPI ROBUSTA 250g | F6: 5 | G6: Rp.30.000 | H6: 150000 | I6: Depok | J6: Kartu debit | M6: =DATEVALUE(SUBSTITUTE(SUBSTITUTE(SUBSTITUTE(SUBSTITUTE(SUBSTITUTE(SUBSTITUTE(SUBSTITUTE(SUBSTITUTE(SUBSTITUTE(SUBSTITUTE(SUBSTITUTE(SUBSTITUTE(Table1[[#This Row],[Tanggal]],"Jan", "Jan"),"Feb","Feb"),"Mar","Mar"),"Apr","Apr"),"Mei","May"),"Jun","Jun"),"Jul","Jul"),"Agu","Aug"),"Sep","Sep"),"Okt","Oct"),"Nov","Nov"),"Des","Dec")) -> 44927 | N6: =Table1[[#This Row],[ID_Transaksi]] -> INV-1005 | O6: Toko Abadi | P6: =PROPER(TRIM(Table1[[#This Row],[Kategori_Produk]])) -> Makanan | Q6: =PROPER(TRIM(Table1[Nama Produk])) -> Kopi Robusta 250G | R6: =Table1[[#This Row],[Qty]] -> 5 | S6: =SUBSTITUTE(SUBSTITUTE(Table1[[#This Row],[Harga_Satuan]],"Rp.",""),".","") -> 30000 | T6: =Table1[[#This Row],[Total_Penjualan]] -> 150000 | U6: =PROPER(Table1[[#This Row],[Kota]]) -> Depok | V6: =PROPER(Table1[[#This Row],[Metode_Pembayaran]]) -> Kartu Debit
A7: 02/01/2023 | B7: TRX-1006 | C7: Pasar Jaya | D7: Pakaian | E7: Kaos Oblong Pria | F7: 4 | G7: 50000 | H7: 200000 | I7: medan | J7: TUNAI | M7: =DATEVALUE(SUBSTITUTE(SUBSTITUTE(SUBSTITUTE(SUBSTITUTE(SUBSTITUTE(SUBSTITUTE(SUBSTITUTE(SUBSTITUTE(SUBSTITUTE(SUBSTITUTE(SUBSTITUTE(SUBSTITUTE(Table1[[#This Row],[Tanggal]],"Jan", "Jan"),"Feb","Feb"),"Mar","Mar"),"Apr","Apr"),"Mei","May"),"Jun","Jun"),"Jul","Jul"),"Agu","Aug"),"Sep","Sep"),"Okt","Oct"),"Nov","Nov"),"Des","Dec")) -> 44928 | N7: =Table1[[#This Row],[ID_Transaksi]] -> TRX-1006 | O7: Pasar Jaya | P7: =PROPER(TRIM(Table1[[#This Row],[Kategori_Produk]])) -> Pakaian | Q7: =PROPER(TRIM(Table1[Nama Produk])) -> Kaos Oblong Pria | R7: =Table1[[#This Row],[Qty]] -> 4 | S7: =SUBSTITUTE(SUBSTITUTE(Table1[[#This Row],[Harga_Satuan]],"Rp.",""),".","") -> 50000 | T7: =Table1[[#This Row],[Total_Penjualan]] -> 200000 | U7: =PROPER(Table1[[#This Row],[Kota]]) -> Medan | V7: =PROPER(Table1[[#This Row],[Metode_Pembayaran]]) -> Tunai
A8: 15/01/2023 | B8: INV-1007 | C8: Minimarket Sejahtera | D8: mainan | E8: Mobil Mainan Plastik | F8: 1 | G8: 15000 | H8: 15000 | I8: Bandung | J8: Kartu Kredit | M8: =DATEVALUE(SUBSTITUTE(SUBSTITUTE(SUBSTITUTE(SUBSTITUTE(SUBSTITUTE(SUBSTITUTE(SUBSTITUTE(SUBSTITUTE(SUBSTITUTE(SUBSTITUTE(SUBSTITUTE(SUBSTITUTE(Table1[[#This Row],[Tanggal]],"Jan", "Jan"),"Feb","Feb"),"Mar","Mar"),"Apr","Apr"),"Mei","May"),"Jun","Jun"),"Jul","Jul"),"Agu","Aug"),"Sep","Sep"),"Okt","Oct"),"Nov","Nov"),"Des","Dec")) -> 44941 | N8: =Table1[[#This Row],[ID_Transaksi]] -> INV-1007 | O8: Minimarket Sejahtera | P8: =PROPER(TRIM(Table1[[#This Row],[Kategori_Produk]])) -> Mainan | Q8: =PROPER(TRIM(Table1[Nama Produk])) -> Mobil Mainan Plastik | R8: =Table1[[#This Row],[Qty]] -> 1 | S8: =SUBSTITUTE(SUBSTITUTE(Table1[[#This Row],[Harga_Satuan]],"Rp.",""),".","") -> 15000 | T8: =Table1[[#This Row],[Total_Penjualan]] -> 15000 | U8: =PROPER(Table1[[#This Row],[Kota]]) -> Bandung | V8: =PROPER(Table1[[#This Row],[Metode_Pembayaran]]) -> Kartu Kredit
A9: 28/01/2023 | B9: TRX-1008 | C9: Toko Sari | D9: Makanan | E9: Snack Keripik Kentang | F9: 8 | G9: 12500 | H9: 100000 | I9: Semarang | J9: tunai | M9: =DATEVALUE(SUBSTITUTE(SUBSTITUTE(SUBSTITUTE(SUBSTITUTE(SUBSTITUTE(SUBSTITUTE(SUBSTITUTE(SUBSTITUTE(SUBSTITUTE(SUBSTITUTE(SUBSTITUTE(SUBSTITUTE(Table1[[#This Row],[Tanggal]],"Jan", "Jan"),"Feb","Feb"),"Mar","Mar"),"Apr","Apr"),"Mei","May"),"Jun","Jun"),"Jul","Jul"),"Agu","Aug"),"Sep","Sep"),"Okt","Oct"),"Nov","Nov"),"Des","Dec")) -> 44954 | N9: =Table1[[#This Row],[ID_Transaksi]] -> TRX-1008 | O9: Toko Sari | P9: =PROPER(TRIM(Table1[[#This Row],[Kategori_Produk]])) -> Makanan | Q9: =PROPER(TRIM(Table1[Nama Produk])) -> Snack Keripik Kentang | R9: =Table1[[#This Row],[Qty]] -> 8 | S9: =SUBSTITUTE(SUBSTITUTE(Table1[[#This Row],[Harga_Satuan]],"Rp.",""),".","") -> 12500 | T9: =Table1[[#This Row],[Total_Penjualan]] -> 100000 | U9: =PROPER(Table1[[#This Row],[Kota]]) -> Semarang | V9: =PROPER(Table1[[#This Row],[Metode_Pembayaran]]) -> Tunai
A10: 05/02/2023 | B10: INV-1009 | C10: Gudang Murah | D10: Minuman | E10: Teh Celup Kotak Kecil | F10: 2 | G10: 7000 | H10: 14000 | I10: Surabaya | J10: KARTU DEBIT | M10: =DATEVALUE(SUBSTITUTE(SUBSTITUTE(SUBSTITUTE(SUBSTITUTE(SUBSTITUTE(SUBSTITUTE(SUBSTITUTE(SUBSTITUTE(SUBSTITUTE(SUBSTITUTE(SUBSTITUTE(SUBSTITUTE(Table1[[#This Row],[Tanggal]],"Jan", "Jan"),"Feb","Feb"),"Mar","Mar"),"Apr","Apr"),"Mei","May"),"Jun","Jun"),"Jul","Jul"),"Agu","Aug"),"Sep","Sep"),"Okt","Oct"),"Nov","Nov"),"Des","Dec")) -> 44962 | N10: =Table1[[#This Row],[ID_Transaksi]] -> INV-1009 | O10: Gudang Murah | P10: =PROPER(TRIM(Table1[[#This Row],[Kategori_Produk]])) -> Minuman | Q10: =PROPER(TRIM(Table1[Nama Produk])) -> Teh Celup Kotak Kecil | R10: =Table1[[#This Row],[Qty]] -> 2 | S10: =SUBSTITUTE(SUBSTITUTE(Table1[[#This Row],[Harga_Satuan]],"Rp.",""),".","") -> 7000 | T10: =Table1[[#This Row],[Total_Penjualan]] -> 14000 | U10: =PROPER(Table1[[#This Row],[Kota]]) -> Surabaya | V10: =PROPER(Table1[[#This Row],[Metode_Pembayaran]]) -> Kartu Debit
A11: 11/02/2023 | B11: INV-1010 | C11: " Toko Sembako" | D11: ELEKTRONIK | E11: Baterai AA Pack 4 | F11: 3 | G11: 30000 | H11: 90000 | I11: Denpasar | J11: Kartu kredit | M11: =DATEVALUE(SUBSTITUTE(SUBSTITUTE(SUBSTITUTE(SUBSTITUTE(SUBSTITUTE(SUBSTITUTE(SUBSTITUTE(SUBSTITUTE(SUBSTITUTE(SUBSTITUTE(SUBSTITUTE(SUBSTITUTE(Table1[[#This Row],[Tanggal]],"Jan", "Jan"),"Feb","Feb"),"Mar","Mar"),"Apr","Apr"),"Mei","May"),"Jun","Jun"),"Jul","Jul"),"Agu","Aug"),"Sep","Sep"),"Okt","Oct"),"Nov","Nov"),"Des","Dec")) -> 44968 | N11: INV-1009 | O11: =PROPER(TRIM(SUBSTITUTE(Table1[[#This Row],[Nama_Toko]],"""",""))) -> Toko Sembako | P11: =PROPER(TRIM(Table1[[#This Row],[Kategori_Produk]])) -> Elektronik | Q11: =PROPER(TRIM(Table1[Nama Produk])) -> Baterai Aa Pack 4 | R11: =Table1[[#This Row],[Qty]] -> 3 | S11: =SUBSTITUTE(SUBSTITUTE(Table1[[#This Row],[Harga_Satuan]],"Rp.",""),".","") -> 30000 | T11: =Table1[[#This Row],[Total_Penjualan]] -> 90000 | U11: =PROPER(Table1[[#This Row],[Kota]]) -> Denpasar | V11: =PROPER(Table1[[#This Row],[Metode_Pembayaran]]) -> Kartu Kredit
A12: 22/02/2023 | B12: TRX-1011 | C12: Warung Depan | D12: kecantikan | E12: Shampoo Anti Ketombe | F12: 1 | G12: 22000 | H12: 22000 | I12: JAKARTA BARAT | J12: TUNAI | M12: =DATEVALUE(SUBSTITUTE(SUBSTITUTE(SUBSTITUTE(SUBSTITUTE(SUBSTITUTE(SUBSTITUTE(SUBSTITUTE(SUBSTITUTE(SUBSTITUTE(SUBSTITUTE(SUBSTITUTE(SUBSTITUTE(Table1[[#This Row],[Tanggal]],"Jan", "Jan"),"Feb","Feb"),"Mar","Mar"),"Apr","Apr"),"Mei","May"),"Jun","Jun"),"Jul","Jul"),"Agu","Aug"),"Sep","Sep"),"Okt","Oct"),"Nov","Nov"),"Des","Dec")) -> 44979 | N12: =Table1[[#This Row],[ID_Transaksi]] -> TRX-1011 | O12: =PROPER(TRIM(SUBSTITUTE(Table1[[#This Row],[Nama_Toko]],"""",""))) -> Warung Depan | P12: =PROPER(TRIM(Table1[[#This Row],[Kategori_Produk]])) -> Kecantikan | Q12: =PROPER(TRIM(Table1[Nama Produk])) -> Shampoo Anti Ketombe | R12: =Table1[[#This Row],[Qty]] -> 1 | S12: =SUBSTITUTE(SUBSTITUTE(Table1[[#This Row],[Harga_Satuan]],"Rp.",""),".","") -> 22000 | T12: =Table1[[#This Row],[Total_Penjualan]] -> 22000 | U12: =PROPER(Table1[[#This Row],[Kota]]) -> Jakarta Barat | V12: =PROPER(Table1[[#This Row],[Metode_Pembayaran]]) -> Tunai
A13: 03/03/2023 | B13: INV-1012 | C13: Toko Hoki | D13: MAKANAN | E13: BISKUIT RASA COKLAT | F13: 6 | G13: 8000 | H13: 48000 | I13: Malang | J13: Kartu debit | M13: =DATEVALUE(SUBSTITUTE(SUBSTITUTE(SUBSTITUTE(SUBSTITUTE(SUBSTITUTE(SUBSTITUTE(SUBSTITUTE(SUBSTITUTE(SUBSTITUTE(SUBSTITUTE(SUBSTITUTE(SUBSTITUTE(Table1[[#This Row],[Tanggal]],"Jan", "Jan"),"Feb","Feb"),"Mar","Mar"),"Apr","Apr"),"Mei","May"),"Jun","Jun"),"Jul","Jul"),"Agu","Aug"),"Sep","Sep"),"Okt","Oct"),"Nov","Nov"),"Des","Dec")) -> 44988 | N13: =Table1[[#This Row],[ID_Transaksi]] -> INV-1012 | O13: =PROPER(TRIM(SUBSTITUTE(Table1[[#This Row],[Nama_Toko]],"""",""))) -> Toko Hoki | P13: =PROPER(TRIM(Table1[[#This Row],[Kategori_Produk]])) -> Makanan | Q13: =PROPER(TRIM(Table1[Nama Produk])) -> Biskuit Rasa Coklat | R13: =Table1[[#This Row],[Qty]] -> 6 | S13: =SUBSTITUTE(SUBSTITUTE(Table1[[#This Row],[Harga_Satuan]],"Rp.",""),".","") -> 8000 | T13: =Table1[[#This Row],[Total_Penjualan]] -> 48000 | U13: =PROPER(Table1[[#This Row],[Kota]]) -> Malang | V13: =PROPER(Table1[[#This Row],[Metode_Pembayaran]]) -> Kartu Debit
A14: 10/03/2023 | B14: TRX-1013 | C14: Pasar Rame | D14: Pakaian | E14: Celana Jeans Biru | F14: 1 | G14: 350000 | H14: 350000 | I14: yogyakarta | J14: Kartu Kredit | M14: =DATEVALUE(SUBSTITUTE(SUBSTITUTE(SUBSTITUTE(SUBSTITUTE(SUBSTITUTE(SUBSTITUTE(SUBSTITUTE(SUBSTITUTE(SUBSTITUTE(SUBSTITUTE(SUBSTITUTE(SUBSTITUTE(Table1[[#This Row],[Tanggal]],"Jan", "Jan"),"Feb","Feb"),"Mar","Mar"),"Apr","Apr"),"Mei","May"),"Jun","Jun"),"Jul","Jul"),"Agu","Aug"),"Sep","Sep"),"Okt","Oct"),"Nov","Nov"),"Des","Dec")) -> 44995 | N14: =Table1[[#This Row],[ID_Transaksi]] -> TRX-1013 | O14: =PROPER(TRIM(SUBSTITUTE(Table1[[#This Row],[Nama_Toko]],"""",""))) -> Pasar Rame | P14: =PROPER(TRIM(Table1[[#This Row],[Kategori_Produk]])) -> Pakaian | Q14: =PROPER(TRIM(Table1[Nama Produk])) -> Celana Jeans Biru | R14: =Table1[[#This Row],[Qty]] -> 1 | S14: =SUBSTITUTE(SUBSTITUTE(Table1[[#This Row],[Harga_Satuan]],"Rp.",""),".","") -> 350000 | T14: =Table1[[#This Row],[Total_Penjualan]] -> 350000 | U14: =PROPER(Table1[[#This Row],[Kota]]) -> Yogyakarta | V14: =PROPER(Table1[[#This Row],[Metode_Pembayaran]]) -> Kartu Kredit
A15: 17/03/2023 | B15: INV-1014 | C15: Grosir Laris | D15: mainan | E15: Boneka Barbie Original | F15: 1 | G15: 75000 | H15: 150000 | I15: MEDAN | J15: tunai | M15: =DATEVALUE(SUBSTITUTE(SUBSTITUTE(SUBSTITUTE(SUBSTITUTE(SUBSTITUTE(SUBSTITUTE(SUBSTITUTE(SUBSTITUTE(SUBSTITUTE(SUBSTITUTE(SUBSTITUTE(SUBSTITUTE(Table1[[#This Row],[Tanggal]],"Jan", "Jan"),"Feb","Feb"),"Mar","Mar"),"Apr","Apr"),"Mei","May"),"Jun","Jun"),"Jul","Jul"),"Agu","Aug"),"Sep","Sep"),"Okt","Oct"),"Nov","Nov"),"Des","Dec")) -> 45002 | N15: =Table1[[#This Row],[ID_Transaksi]] -> INV-1014 | O15: =PROPER(TRIM(SUBSTITUTE(Table1[[#This Row],[Nama_Toko]],"""",""))) -> Grosir Laris | P15: =PROPER(TRIM(Table1[[#This Row],[Kategori_Produk]])) -> Mainan | Q15: =PROPER(TRIM(Table1[Nama Produk])) -> Boneka Barbie Original | R15: =Table1[[#This Row],[Qty]] -> 1 | S15: =SUBSTITUTE(SUBSTITUTE(Table1[[#This Row],[Harga_Satuan]],"Rp.",""),".","") -> 75000 | T15: =Table1[[#This Row],[Total_Penjualan]] -> 150000 | U15: =PROPER(Table1[[#This Row],[Kota]]) -> Medan | V15: =PROPER(Table1[[#This Row],[Metode_Pembayaran]]) -> Tunai
A16: 25/03/2023 | B16: TRX-1015 | C16: Minimarket Cepat | D16: Makanan | E16: Sereal Sarapan Kotak | F16: 4 | G16: 28000 | H16: 112000 | I16: Bandung | J16: TUNAI | M16: =DATEVALUE(SUBSTITUTE(SUBSTITUTE(SUBSTITUTE(SUBSTITUTE(SUBSTITUTE(SUBSTITUTE(SUBSTITUTE(SUBSTITUTE(SUBSTITUTE(SUBSTITUTE(SUBSTITUTE(SUBSTITUTE(Table1[[#This Row],[Tanggal]],"Jan", "Jan"),"Feb","Feb"),"Mar","Mar"),"Apr","Apr"),"Mei","May"),"Jun","Jun"),"Jul","Jul"),"Agu","Aug"),"Sep","Sep"),"Okt","Oct"),"Nov","Nov"),"Des","Dec")) -> 45010 | N16: =Table1[[#This Row],[ID_Transaksi]] -> TRX-1015 | O16: =PROPER(TRIM(SUBSTITUTE(Table1[[#This Row],[Nama_Toko]],"""",""))) -> Minimarket Cepat | P16: =PROPER(TRIM(Table1[[#This Row],[Kategori_Produk]])) -> Makanan | Q16: =PROPER(TRIM(Table1[Nama Produk])) -> Sereal Sarapan Kotak | R16: =Table1[[#This Row],[Qty]] -> 4 | S16: =SUBSTITUTE(SUBSTITUTE(Table1[[#This Row],[Harga_Satuan]],"Rp.",""),".","") -> 28000 | T16: =Table1[[#This Row],[Total_Penjualan]] -> 112000 | U16: =PROPER(Table1[[#This Row],[Kota]]) -> Bandung | V16: =PROPER(Table1[[#This Row],[Metode_Pembayaran]]) -> Tunai
A17: 01/04/2023 | B17: INV-1016 | C17: Toko Murni | D17: Minuman | E17: Jus Buah Segar 1L | F17: 2 | G17: 20000 | H17: 40000 | I17: semarang | J17: Kartu debit | M17: =DATEVALUE(SUBSTITUTE(SUBSTITUTE(SUBSTITUTE(SUBSTITUTE(SUBSTITUTE(SUBSTITUTE(SUBSTITUTE(SUBSTITUTE(SUBSTITUTE(SUBSTITUTE(SUBSTITUTE(SUBSTITUTE(Table1[[#This Row],[Tanggal]],"Jan", "Jan"),"Feb","Feb"),"Mar","Mar"),"Apr","Apr"),"Mei","May"),"Jun","Jun"),"Jul","Jul"),"Agu","Aug"),"Sep","Sep"),"Okt","Oct"),"Nov","Nov"),"Des","Dec")) -> 45017 | N17: =Table1[[#This Row],[ID_Transaksi]] -> INV-1016 | O17: =PROPER(TRIM(SUBSTITUTE(Table1[[#This Row],[Nama_Toko]],"""",""))) -> Toko Murni | P17: =PROPER(TRIM(Table1[[#This Row],[Kategori_Produk]])) -> Minuman | Q17: =PROPER(TRIM(Table1[Nama Produk])) -> Jus Buah Segar 1L | R17: =Table1[[#This Row],[Qty]] -> 2 | S17: =SUBSTITUTE(SUBSTITUTE(Table1[[#This Row],[Harga_Satuan]],"Rp.",""),".","") -> 20000 | T17: =Table1[[#This Row],[Total_Penjualan]] -> 40000 | U17: =PROPER(Table1[[#This Row],[Kota]]) -> Semarang | V17: =PROPER(Table1[[#This Row],[Metode_Pembayaran]]) -> Kartu Debit
A18: 10/04/2023 | B18: TRX-1017 | C18: Warung Santai | D18: ELEKTRONIK | E18: Kabel Data USB C | F18: 5 | G18: 15000 | H18: 75000 | I18: Surabaya | J18: KARTU KREDIT | M18: =DATEVALUE(SUBSTITUTE(SUBSTITUTE(SUBSTITUTE(SUBSTITUTE(SUBSTITUTE(SUBSTITUTE(SUBSTITUTE(SUBSTITUTE(SUBSTITUTE(SUBSTITUTE(SUBSTITUTE(SUBSTITUTE(Table1[[#This Row],[Tanggal]],"Jan", "Jan"),"Feb","Feb"),"Mar","Mar"),"Apr","Apr"),"Mei","May"),"Jun","Jun"),"Jul","Jul"),"Agu","Aug"),"Sep","Sep"),"Okt","Oct"),"Nov","Nov"),"Des","Dec")) -> 45026 | N18: =Table1[[#This Row],[ID_Transaksi]] -> TRX-1017 | O18: =PROPER(TRIM(SUBSTITUTE(Table1[[#This Row],[Nama_Toko]],"""",""))) -> Warung Santai | P18: =PROPER(TRIM(Table1[[#This Row],[Kategori_Produk]])) -> Elektronik | Q18: =PROPER(TRIM(Table1[Nama Produk])) -> Kabel Data Usb C | R18: =Table1[[#This Row],[Qty]] -> 5 | S18: =SUBSTITUTE(SUBSTITUTE(Table1[[#This Row],[Harga_Satuan]],"Rp.",""),".","") -> 15000 | T18: =Table1[[#This Row],[Total_Penjualan]] -> 75000 | U18: =PROPER(Table1[[#This Row],[Kota]]) -> Surabaya | V18: =PROPER(Table1[[#This Row],[Metode_Pembayaran]]) -> Kartu Kredit
A19: 20/04/2023 | B19: INV-1018 | C19: Gudang Besar | D19: kecantikan | E19: Lipstik Warna Merah | F19: 1 | G19: 55000 | H19: 55000 | I19: DENPASAR | J19: tunai | M19: =DATEVALUE(SUBSTITUTE(SUBSTITUTE(SUBSTITUTE(SUBSTITUTE(SUBSTITUTE(SUBSTITUTE(SUBSTITUTE(SUBSTITUTE(SUBSTITUTE(SUBSTITUTE(SUBSTITUTE(SUBSTITUTE(Table1[[#This Row],[Tanggal]],"Jan", "Jan"),"Feb","Feb"),"Mar","Mar"),"Apr","Apr"),"Mei","May"),"Jun","Jun"),"Jul","Jul"),"Agu","Aug"),"Sep","Sep"),"Okt","Oct"),"Nov","Nov"),"Des","Dec")) -> 45036 | N19: =Table1[[#This Row],[ID_Transaksi]] -> INV-1018 | O19: =PROPER(TRIM(SUBSTITUTE(Table1[[#This Row],[Nama_Toko]],"""",""))) -> Gudang Besar | P19: =PROPER(TRIM(Table1[[#This Row],[Kategori_Produk]])) -> Kecantikan | Q19: =PROPER(TRIM(Table1[Nama Produk])) -> Lipstik Warna Merah | R19: =Table1[[#This Row],[Qty]] -> 1 | S19: =SUBSTITUTE(SUBSTITUTE(Table1[[#This Row],[Harga_Satuan]],"Rp.",""),".","") -> 55000 | T19: =Table1[[#This Row],[Total_Penjualan]] -> 55000 | U19: =PROPER(Table1[[#This Row],[Kota]]) -> Denpasar | V19: =PROPER(Table1[[#This Row],[Metode_Pembayaran]]) -> Tunai
A20: 01-Mei-2023 | B20: TRX-1019 | C20: Gudang Besar | D20: MAKANAN | E20: TEPUNG TERIGU 1 KG | F20: 10 | G20: 11000 | H20: 110000 | I20: Jakarta | J20: Kartu debit | M20: =DATEVALUE(SUBSTITUTE(SUBSTITUTE(SUBSTITUTE(SUBSTITUTE(SUBSTITUTE(SUBSTITUTE(SUBSTITUTE(SUBSTITUTE(SUBSTITUTE(SUBSTITUTE(SUBSTITUTE(SUBSTITUTE(Table1[[#This Row],[Tanggal]],"Jan", "Jan"),"Feb","Feb"),"Mar","Mar"),"Apr","Apr"),"Mei","May"),"Jun","Jun"),"Jul","Jul"),"Agu","Aug"),"Sep","Sep"),"Okt","Oct"),"Nov","Nov"),"Des","Dec")) -> 45047 | N20: =Table1[[#This Row],[ID_Transaksi]] -> TRX-1019 | O20: =PROPER(TRIM(SUBSTITUTE(Table1[[#This Row],[Nama_Toko]],"""",""))) -> Gudang Besar | P20: =PROPER(TRIM(Table1[[#This Row],[Kategori_Produk]])) -> Makanan | Q20: =PROPER(TRIM(Table1[Nama Produk])) -> Tepung Terigu 1 Kg | R20: =Table1[[#This Row],[Qty]] -> 10 | S20: =SUBSTITUTE(SUBSTITUTE(Table1[[#This Row],[Harga_Satuan]],"Rp.",""),".","") -> 11000 | T20: =Table1[[#This Row],[Total_Penjualan]] -> 110000 | U20: =PROPER(Table1[[#This Row],[Kota]]) -> Jakarta | V20: =PROPER(Table1[[#This Row],[Metode_Pembayaran]]) -> Kartu Debit
A21: 10/05/2023 | B21: INV-1020 | C21: Pasar Pagi | D21: Pakaian | E21: Kemeja Batik Lengan Panjang | F21: 3 | G21: 120000 | H21: 360000 | I21: medan | J21: TUNAI | M21: =DATEVALUE(SUBSTITUTE(SUBSTITUTE(SUBSTITUTE(SUBSTITUTE(SUBSTITUTE(SUBSTITUTE(SUBSTITUTE(SUBSTITUTE(SUBSTITUTE(SUBSTITUTE(SUBSTITUTE(SUBSTITUTE(Table1[[#This Row],[Tanggal]],"Jan", "Jan"),"Feb","Feb"),"Mar","Mar"),"Apr","Apr"),"Mei","May"),"Jun","Jun"),"Jul","Jul"),"Agu","Aug"),"Sep","Sep"),"Okt","Oct"),"Nov","Nov"),"Des","Dec")) -> 45056 | N21: =Table1[[#This Row],[ID_Transaksi]] -> INV-1020 | O21: =PROPER(TRIM(SUBSTITUTE(Table1[[#This Row],[Nama_Toko]],"""",""))) -> Pasar Pagi | P21: =PROPER(TRIM(Table1[[#This Row],[Kategori_Produk]])) -> Pakaian | Q21: =PROPER(TRIM(Table1[Nama Produk])) -> Kemeja Batik Lengan Panjang | R21: =Table1[[#This Row],[Qty]] -> 3 | S21: =SUBSTITUTE(SUBSTITUTE(Table1[[#This Row],[Harga_Satuan]],"Rp.",""),".","") -> 120000 | T21: =Table1[[#This Row],[Total_Penjualan]] -> 360000 | U21: =PROPER(Table1[[#This Row],[Kota]]) -> Medan | V21: =PROPER(Table1[[#This Row],[Metode_Pembayaran]]) -> Tunai
A22: 21/05/2023 | B22: TRX-1021 | C22: Minimarket Istimewa | D22: mainan | E22: Puzzle Kayu Edukasi | F22: 2 | G22: 45000 | H22: 90000 | I22: yogyakarta | J22: Kartu Kredit | M22: =DATEVALUE(SUBSTITUTE(SUBSTITUTE(SUBSTITUTE(SUBSTITUTE(SUBSTITUTE(SUBSTITUTE(SUBSTITUTE(SUBSTITUTE(SUBSTITUTE(SUBSTITUTE(SUBSTITUTE(SUBSTITUTE(Table1[[#This Row],[Tanggal]],"Jan", "Jan"),"Feb","Feb"),"Mar","Mar"),"Apr","Apr"),"Mei","May"),"Jun","Jun"),"Jul","Jul"),"Agu","Aug"),"Sep","Sep"),"Okt","Oct"),"Nov","Nov"),"Des","Dec")) -> 45067 | N22: =Table1[[#This Row],[ID_Transaksi]] -> TRX-1021 | O22: =PROPER(TRIM(SUBSTITUTE(Table1[[#This Row],[Nama_Toko]],"""",""))) -> Minimarket Istimewa | P22: =PROPER(TRIM(Table1[[#This Row],[Kategori_Produk]])) -> Mainan | Q22: =PROPER(TRIM(Table1[Nama Produk])) -> Puzzle Kayu Edukasi | R22: =Table1[[#This Row],[Qty]] -> 2 | S22: =SUBSTITUTE(SUBSTITUTE(Table1[[#This Row],[Harga_Satuan]],"Rp.",""),".","") -> 45000 | T22: =Table1[[#This Row],[Total_Penjualan]] -> 90000 | U22: =PROPER(Table1[[#This Row],[Kota]]) -> Yogyakarta | V22: =PROPER(Table1[[#This Row],[Metode_Pembayaran]]) -> Kartu Kredit
A23: 01/06/2023 | B23: INV-1022 | C23: Toko Serba Ada | D23: Makanan | E23: Telur Ayam Ras Pack 10 | F23: 12 | G23: 20000 | H23: 240000 | I23: Malang | J23: tunai | M23: =DATEVALUE(SUBSTITUTE(SUBSTITUTE(SUBSTITUTE(SUBSTITUTE(SUBSTITUTE(SUBSTITUTE(SUBSTITUTE(SUBSTITUTE(SUBSTITUTE(SUBSTITUTE(SUBSTITUTE(SUBSTITUTE(Table1[[#This Row],[Tanggal]],"Jan", "Jan"),"Feb","Feb"),"Mar","Mar"),"Apr","Apr"),"Mei","May"),"Jun","Jun"),"Jul","Jul"),"Agu","Aug"),"Sep","Sep"),"Okt","Oct"),"Nov","Nov"),"Des","Dec")) -> 45078 | N23: =Table1[[#This Row],[ID_Transaksi]] -> INV-1022 | O23: =PROPER(TRIM(SUBSTITUTE(Table1[[#This Row],[Nama_Toko]],"""",""))) -> Toko Serba Ada | P23: =PROPER(TRIM(Table1[[#This Row],[Kategori_Produk]])) -> Makanan | Q23: =PROPER(TRIM(Table1[Nama Produk])) -> Telur Ayam Ras Pack 10 | R23: =Table1[[#This Row],[Qty]] -> 12 | S23: =SUBSTITUTE(SUBSTITUTE(Table1[[#This Row],[Harga_Satuan]],"Rp.",""),".","") -> 20000 | T23: =Table1[[#This Row],[Total_Penjualan]] -> 240000 | U23: =PROPER(Table1[[#This Row],[Kota]]) -> Malang | V23: =PROPER(Table1[[#This Row],[Metode_Pembayaran]]) -> Tunai
... A32: 01/09/2023 | B32: TRX-1031 | C32: Warung Kita | D32: ELEKTRONIK | E32: Headset Bluetooth | F32: 2 | G32: 85000 | H32: 170000 | I32: Bandung | J32: KARTU KREDIT | M32: =DATEVALUE(SUBSTITUTE(SUBSTITUTE(SUBSTITUTE(SUBSTITUTE(SUBSTITUTE(SUBSTITUTE(SUBSTITUTE(SUBSTITUTE(SUBSTITUTE(SUBSTITUTE(SUBSTITUTE(SUBSTITUTE(Table1[[#This Row],[Tanggal]],"Jan", "Jan"),"Feb","Feb"),"Mar","Mar"),"Apr","Apr"),"Mei","May"),"Jun","Jun"),"Jul","Jul"),"Agu","Aug"),"Sep","Sep"),"Okt","Oct"),"Nov","Nov"),"Des","Dec")) -> 45170 | N32: =Table1[[#This Row],[ID_Transaksi]] -> TRX-1031 | O32: =PROPER(TRIM(SUBSTITUTE(Table1[[#This Row],[Nama_Toko]],"""",""))) -> Warung Kita | P32: =PROPER(TRIM(Table1[[#This Row],[Kategori_Produk]])) -> Elektronik | Q32: =PROPER(TRIM(Table1[Nama Produk])) -> Headset Bluetooth | R32: =Table1[[#This Row],[Qty]] -> 2 | S32: =SUBSTITUTE(SUBSTITUTE(Table1[[#This Row],[Harga_Satuan]],"Rp.",""),".","") -> 85000 | T32: =Table1[[#This Row],[Total_Penjualan]] -> 170000 | U32: =PROPER(Table1[[#This Row],[Kota]]) -> Bandung | V32: =PROPER(Table1[[#This Row],[Metode_Pembayaran]]) -> Kartu Kredit
A33: 10/09/2023 | C33: " Gudang Kecil " | D33: kecantikan | E33: Parfum Wanita EDP 50ml | F33: 1 | G33: 300000 | H33: 300000 | I33: Semarang | J33: tunai | M33: =DATEVALUE(SUBSTITUTE(SUBSTITUTE(SUBSTITUTE(SUBSTITUTE(SUBSTITUTE(SUBSTITUTE(SUBSTITUTE(SUBSTITUTE(SUBSTITUTE(SUBSTITUTE(SUBSTITUTE(SUBSTITUTE(Table1[[#This Row],[Tanggal]],"Jan", "Jan"),"Feb","Feb"),"Mar","Mar"),"Apr","Apr"),"Mei","May"),"Jun","Jun"),"Jul","Jul"),"Agu","Aug"),"Sep","Sep"),"Okt","Oct"),"Nov","Nov"),"Des","Dec")) -> 45179 | N33: =Table1[[#This Row],[ID_Transaksi]] -> 0 | O33: =PROPER(TRIM(SUBSTITUTE(Table1[[#This Row],[Nama_Toko]],"""",""))) -> Gudang Kecil | P33: =PROPER(TRIM(Table1[[#This Row],[Kategori_Produk]])) -> Kecantikan | Q33: =PROPER(TRIM(Table1[Nama Produk])) -> Parfum Wanita Edp 50Ml | R33: =Table1[[#This Row],[Qty]] -> 1 | S33: =SUBSTITUTE(SUBSTITUTE(Table1[[#This Row],[Harga_Satuan]],"Rp.",""),".","") -> 300000 | T33: =Table1[[#This Row],[Total_Penjualan]] -> 300000 | U33: =PROPER(Table1[[#This Row],[Kota]]) -> Semarang | V33: =PROPER(Table1[[#This Row],[Metode_Pembayaran]]) -> Tunai
A34: 20/09/2023 | B34: INV-1033 | C34: Toko Maju | D34: MAKANAN | E34: KEJU CHEDDAR BLOK | F34: 3 | G34: 35000 | H34: 105000 | I34: surabaya | J34: Kartu debit | M34: =DATEVALUE(SUBSTITUTE(SUBSTITUTE(SUBSTITUTE(SUBSTITUTE(SUBSTITUTE(SUBSTITUTE(SUBSTITUTE(SUBSTITUTE(SUBSTITUTE(SUBSTITUTE(SUBSTITUTE(SUBSTITUTE(Table1[[#This Row],[Tanggal]],"Jan", "Jan"),"Feb","Feb"),"Mar","Mar"),"Apr","Apr"),"Mei","May"),"Jun","Jun"),"Jul","Jul"),"Agu","Aug"),"Sep","Sep"),"Okt","Oct"),"Nov","Nov"),"Des","Dec")) -> 45189 | N34: =Table1[[#This Row],[ID_Transaksi]] -> INV-1033 | O34: =PROPER(TRIM(SUBSTITUTE(Table1[[#This Row],[Nama_Toko]],"""",""))) -> Toko Maju | P34: =PROPER(TRIM(Table1[[#This Row],[Kategori_Produk]])) -> Makanan | Q34: =PROPER(TRIM(Table1[Nama Produk])) -> Keju Cheddar Blok | R34: =Table1[[#This Row],[Qty]] -> 3 | S34: =SUBSTITUTE(SUBSTITUTE(Table1[[#This Row],[Harga_Satuan]],"Rp.",""),".","") -> 35000 | T34: =Table1[[#This Row],[Total_Penjualan]] -> 105000 | U34: =PROPER(Table1[[#This Row],[Kota]]) -> Surabaya | V34: =PROPER(Table1[[#This Row],[Metode_Pembayaran]]) -> Kartu Debit
A35: 01/10/2023 | B35: TRX-1034 | C35: Pasar Senja | D35: Pakaian | E35: Daster Ibu Hamil | F35: 6 | G35: 70000 | H35: 420000 | I35: denpasar | J35: TUNAI | M35: =DATEVALUE(SUBSTITUTE(SUBSTITUTE(SUBSTITUTE(SUBSTITUTE(SUBSTITUTE(SUBSTITUTE(SUBSTITUTE(SUBSTITUTE(SUBSTITUTE(SUBSTITUTE(SUBSTITUTE(SUBSTITUTE(Table1[[#This Row],[Tanggal]],"Jan", "Jan"),"Feb","Feb"),"Mar","Mar"),"Apr","Apr"),"Mei","May"),"Jun","Jun"),"Jul","Jul"),"Agu","Aug"),"Sep","Sep"),"Okt","Oct"),"Nov","Nov"),"Des","Dec")) -> 45200 | N35: =Table1[[#This Row],[ID_Transaksi]] -> TRX-1034 | O35: =PROPER(TRIM(SUBSTITUTE(Table1[[#This Row],[Nama_Toko]],"""",""))) -> Pasar Senja | P35: =PROPER(TRIM(Table1[[#This Row],[Kategori_Produk]])) -> Pakaian | Q35: =PROPER(TRIM(Table1[Nama Produk])) -> Daster Ibu Hamil | R35: =Table1[[#This Row],[Qty]] -> 6 | S35: =SUBSTITUTE(SUBSTITUTE(Table1[[#This Row],[Harga_Satuan]],"Rp.",""),".","") -> 70000 | T35: =Table1[[#This Row],[Total_Penjualan]] -> 420000 | U35: =PROPER(Table1[[#This Row],[Kota]]) -> Denpasar | V35: =PROPER(Table1[[#This Row],[Metode_Pembayaran]]) -> Tunai
